[2025-02-24T10:08:31.281+0800] {local_task_job_runner.py:123} INFO - ::group::Pre task execution logs
[2025-02-24T10:08:31.295+0800] {taskinstance.py:2614} INFO - Dependencies all met for dep_context=non-requeueable deps ti=<TaskInstance: muse_dag.extract_crypto_data scheduled__2025-02-01T00:50:00+00:00 [queued]>
[2025-02-24T10:08:31.310+0800] {taskinstance.py:2614} INFO - Dependencies all met for dep_context=requeueable deps ti=<TaskInstance: muse_dag.extract_crypto_data scheduled__2025-02-01T00:50:00+00:00 [queued]>
[2025-02-24T10:08:31.311+0800] {taskinstance.py:2867} INFO - Starting attempt 2 of 2
[2025-02-24T10:08:31.362+0800] {taskinstance.py:2890} INFO - Executing <Task(BashOperator): extract_crypto_data> on 2025-02-01 00:50:00+00:00
[2025-02-24T10:08:31.367+0800] {standard_task_runner.py:72} INFO - Started process 33455 to run task
[2025-02-24T10:08:31.369+0800] {standard_task_runner.py:104} INFO - Running: ['airflow', 'tasks', 'run', 'muse_dag', 'extract_crypto_data', 'scheduled__2025-02-01T00:50:00+00:00', '--job-id', '14', '--raw', '--subdir', 'DAGS_FOLDER/muse_dag.py', '--cfg-path', '/tmp/tmpjy1sdyjy']
[2025-02-24T10:08:31.379+0800] {standard_task_runner.py:105} INFO - Job 14: Subtask extract_crypto_data
[2025-02-24T10:08:31.475+0800] {task_command.py:467} INFO - Running <TaskInstance: muse_dag.extract_crypto_data scheduled__2025-02-01T00:50:00+00:00 [running]> on host LAPTOP-7NCGBFK9.
[2025-02-24T10:08:31.554+0800] {taskinstance.py:3134} INFO - Exporting env vars: AIRFLOW_CTX_DAG_OWNER='laurence' AIRFLOW_CTX_DAG_ID='muse_dag' AIRFLOW_CTX_TASK_ID='extract_crypto_data' AIRFLOW_CTX_EXECUTION_DATE='2025-02-01T00:50:00+00:00' AIRFLOW_CTX_TRY_NUMBER='2' AIRFLOW_CTX_DAG_RUN_ID='scheduled__2025-02-01T00:50:00+00:00'
[2025-02-24T10:08:31.555+0800] {logging_mixin.py:190} INFO - Task instance is in running state
[2025-02-24T10:08:31.556+0800] {logging_mixin.py:190} INFO -  Previous state of the Task instance: queued
[2025-02-24T10:08:31.557+0800] {logging_mixin.py:190} INFO - Current task name:extract_crypto_data state:running start_date:2025-02-24 02:08:31.297865+00:00
[2025-02-24T10:08:31.558+0800] {logging_mixin.py:190} INFO - Dag name:muse_dag and current dag run status:running
[2025-02-24T10:08:31.559+0800] {taskinstance.py:732} INFO - ::endgroup::
[2025-02-24T10:08:31.562+0800] {subprocess.py:78} INFO - Tmp dir root location: /tmp
[2025-02-24T10:08:31.564+0800] {subprocess.py:88} INFO - Running command: ['/usr/bin/bash', '-c', '/mnt/c/Users/User/laurence/Muse_assessment/muse_env/bin/python3 /mnt/c/Users/User/laurence/Muse_assessment/src/extract_crypto.py']
[2025-02-24T10:08:31.568+0800] {subprocess.py:99} INFO - Output:
[2025-02-24T10:08:44.587+0800] {subprocess.py:106} INFO - Traceback (most recent call last):
[2025-02-24T10:08:44.588+0800] {subprocess.py:106} INFO -   File "/mnt/c/Users/User/laurence/Muse_assessment/src/extract_crypto.py", line 34, in <module>
[2025-02-24T10:08:44.589+0800] {subprocess.py:106} INFO -     logger.addHandler(logging.FileHandler(FILE_PATH)) # Store log to file and show in shell
[2025-02-24T10:08:44.590+0800] {subprocess.py:106} INFO -   File "/usr/lib/python3.10/logging/__init__.py", line 1169, in __init__
[2025-02-24T10:08:44.591+0800] {subprocess.py:106} INFO -     StreamHandler.__init__(self, self._open())
[2025-02-24T10:08:44.591+0800] {subprocess.py:106} INFO -   File "/usr/lib/python3.10/logging/__init__.py", line 1201, in _open
[2025-02-24T10:08:44.592+0800] {subprocess.py:106} INFO -     return open_func(self.baseFilename, self.mode,
[2025-02-24T10:08:44.593+0800] {subprocess.py:106} INFO - FileNotFoundError: [Errno 2] No such file or directory: '/tmp/logs/extract_stock_log.log'
[2025-02-24T10:08:44.794+0800] {subprocess.py:110} INFO - Command exited with return code 1
[2025-02-24T10:08:44.919+0800] {taskinstance.py:3313} ERROR - Task failed with exception
Traceback (most recent call last):
  File "/mnt/c/Users/User/laurence/Muse_assessment/muse_env/lib/python3.10/site-packages/airflow/models/taskinstance.py", line 763, in _execute_task
    result = _execute_callable(context=context, **execute_callable_kwargs)
  File "/mnt/c/Users/User/laurence/Muse_assessment/muse_env/lib/python3.10/site-packages/airflow/models/taskinstance.py", line 734, in _execute_callable
    return ExecutionCallableRunner(
  File "/mnt/c/Users/User/laurence/Muse_assessment/muse_env/lib/python3.10/site-packages/airflow/utils/operator_helpers.py", line 252, in run
    return self.func(*args, **kwargs)
  File "/mnt/c/Users/User/laurence/Muse_assessment/muse_env/lib/python3.10/site-packages/airflow/models/baseoperator.py", line 424, in wrapper
    return func(self, *args, **kwargs)
  File "/mnt/c/Users/User/laurence/Muse_assessment/muse_env/lib/python3.10/site-packages/airflow/operators/bash.py", line 276, in execute
    raise AirflowException(
airflow.exceptions.AirflowException: Bash command failed. The command returned a non-zero exit code 1.
[2025-02-24T10:08:44.963+0800] {logging_mixin.py:190} INFO - Task instance in failure state
[2025-02-24T10:08:44.968+0800] {logging_mixin.py:190} INFO - Task start:2025-02-24 02:08:31.297865+00:00 end:2025-02-24 02:08:44.962733+00:00 duration:13.664868
[2025-02-24T10:08:44.972+0800] {logging_mixin.py:190} INFO - Task:<Task(BashOperator): extract_crypto_data> dag:<DAG: muse_dag> dagrun:<DagRun muse_dag @ 2025-02-01 00:50:00+00:00: scheduled__2025-02-01T00:50:00+00:00, state:running, queued_at: 2025-02-24 01:53:02.819369+00:00. externally triggered: False>
[2025-02-24T10:08:44.976+0800] {logging_mixin.py:190} INFO - Failure caused by Bash command failed. The command returned a non-zero exit code 1.
[2025-02-24T10:08:44.979+0800] {taskinstance.py:1226} INFO - Marking task as FAILED. dag_id=muse_dag, task_id=extract_crypto_data, run_id=scheduled__2025-02-01T00:50:00+00:00, execution_date=20250201T005000, start_date=20250224T020831, end_date=20250224T020844
[2025-02-24T10:08:45.074+0800] {taskinstance.py:341} INFO - ::group::Post task execution logs
[2025-02-24T10:08:45.077+0800] {standard_task_runner.py:124} ERROR - Failed to execute job 14 for task extract_crypto_data (Bash command failed. The command returned a non-zero exit code 1.; 33455)
Traceback (most recent call last):
  File "/mnt/c/Users/User/laurence/Muse_assessment/muse_env/lib/python3.10/site-packages/airflow/task/task_runner/standard_task_runner.py", line 117, in _start_by_fork
    ret = args.func(args, dag=self.dag)
  File "/mnt/c/Users/User/laurence/Muse_assessment/muse_env/lib/python3.10/site-packages/airflow/cli/cli_config.py", line 49, in command
    return func(*args, **kwargs)
  File "/mnt/c/Users/User/laurence/Muse_assessment/muse_env/lib/python3.10/site-packages/airflow/utils/cli.py", line 116, in wrapper
    return f(*args, **kwargs)
  File "/mnt/c/Users/User/laurence/Muse_assessment/muse_env/lib/python3.10/site-packages/airflow/cli/commands/task_command.py", line 483, in task_run
    task_return_code = _run_task_by_selected_method(args, _dag, ti)
  File "/mnt/c/Users/User/laurence/Muse_assessment/muse_env/lib/python3.10/site-packages/airflow/cli/commands/task_command.py", line 256, in _run_task_by_selected_method
    return _run_raw_task(args, ti)
  File "/mnt/c/Users/User/laurence/Muse_assessment/muse_env/lib/python3.10/site-packages/airflow/cli/commands/task_command.py", line 341, in _run_raw_task
    return ti._run_raw_task(
  File "/mnt/c/Users/User/laurence/Muse_assessment/muse_env/lib/python3.10/site-packages/airflow/utils/session.py", line 97, in wrapper
    return func(*args, session=session, **kwargs)
  File "/mnt/c/Users/User/laurence/Muse_assessment/muse_env/lib/python3.10/site-packages/airflow/models/taskinstance.py", line 3006, in _run_raw_task
    return _run_raw_task(
  File "/mnt/c/Users/User/laurence/Muse_assessment/muse_env/lib/python3.10/site-packages/airflow/models/taskinstance.py", line 274, in _run_raw_task
    TaskInstance._execute_task_with_callbacks(
  File "/mnt/c/Users/User/laurence/Muse_assessment/muse_env/lib/python3.10/site-packages/airflow/models/taskinstance.py", line 3161, in _execute_task_with_callbacks
    result = self._execute_task(context, task_orig)
  File "/mnt/c/Users/User/laurence/Muse_assessment/muse_env/lib/python3.10/site-packages/airflow/models/taskinstance.py", line 3185, in _execute_task
    return _execute_task(self, context, task_orig)
  File "/mnt/c/Users/User/laurence/Muse_assessment/muse_env/lib/python3.10/site-packages/airflow/models/taskinstance.py", line 763, in _execute_task
    result = _execute_callable(context=context, **execute_callable_kwargs)
  File "/mnt/c/Users/User/laurence/Muse_assessment/muse_env/lib/python3.10/site-packages/airflow/models/taskinstance.py", line 734, in _execute_callable
    return ExecutionCallableRunner(
  File "/mnt/c/Users/User/laurence/Muse_assessment/muse_env/lib/python3.10/site-packages/airflow/utils/operator_helpers.py", line 252, in run
    return self.func(*args, **kwargs)
  File "/mnt/c/Users/User/laurence/Muse_assessment/muse_env/lib/python3.10/site-packages/airflow/models/baseoperator.py", line 424, in wrapper
    return func(self, *args, **kwargs)
  File "/mnt/c/Users/User/laurence/Muse_assessment/muse_env/lib/python3.10/site-packages/airflow/operators/bash.py", line 276, in execute
    raise AirflowException(
airflow.exceptions.AirflowException: Bash command failed. The command returned a non-zero exit code 1.
[2025-02-24T10:08:45.124+0800] {local_task_job_runner.py:266} INFO - Task exited with return code 1
[2025-02-24T10:08:45.160+0800] {taskinstance.py:3901} INFO - 0 downstream tasks scheduled from follow-on schedule check
[2025-02-24T10:08:45.192+0800] {local_task_job_runner.py:245} INFO - ::endgroup::
